Watching for file changes with StatReloader
Not Found: /favicon.ico
Internal Server Error: /register/
Traceback (most recent call last):
  File "C:\Users\prash\AppData\Local\Programs\Python\Python312\Lib\site-packages\django\core\handlers\exception.py", line 55, in inner
    response = get_response(request)
               ^^^^^^^^^^^^^^^^^^^^^
  File "C:\Users\prash\AppData\Local\Programs\Python\Python312\Lib\site-packages\django\core\handlers\base.py", line 197, in _get_response
    response = wrapped_callback(request, *callback_args, **callback_kwargs)
               ^^^^^^^^^^^^^^^^^^^^^^^^^^^^^^^^^^^^^^^^^^^^^^^^^^^^^^^^^^^^
  File "D:\projects\Auction System\BidBazaar\auctions\views.py", line 79, in register
    send_mail(
  File "C:\Users\prash\AppData\Local\Programs\Python\Python312\Lib\site-packages\django\core\mail\__init__.py", line 88, in send_mail
    return mail.send()
           ^^^^^^^^^^^
  File "C:\Users\prash\AppData\Local\Programs\Python\Python312\Lib\site-packages\django\core\mail\message.py", line 301, in send
    return self.get_connection(fail_silently).send_messages([self])
           ^^^^^^^^^^^^^^^^^^^^^^^^^^^^^^^^^^^^^^^^^^^^^^^^^^^^^^^^
  File "C:\Users\prash\AppData\Local\Programs\Python\Python312\Lib\site-packages\django\core\mail\backends\smtp.py", line 128, in send_messages
    new_conn_created = self.open()
                       ^^^^^^^^^^^
  File "C:\Users\prash\AppData\Local\Programs\Python\Python312\Lib\site-packages\django\core\mail\backends\smtp.py", line 95, in open
    self.connection.login(self.username, self.password)
  File "C:\Users\prash\AppData\Local\Programs\Python\Python312\Lib\smtplib.py", line 750, in login
    raise last_exception
  File "C:\Users\prash\AppData\Local\Programs\Python\Python312\Lib\smtplib.py", line 739, in login
    (code, resp) = self.auth(
                   ^^^^^^^^^^
  File "C:\Users\prash\AppData\Local\Programs\Python\Python312\Lib\smtplib.py", line 662, in auth
    raise SMTPAuthenticationError(code, resp)
smtplib.SMTPAuthenticationError: (535, b'5.7.8 Username and Password not accepted. For more information, go to\n5.7.8  https://support.google.com/mail/?p=BadCredentials 98e67ed59e1d1-3039f1d4b39sm13187897a91.39 - gsmtp')
Bids for listing 1: <QuerySet [<Bid: Bid object (4)>]>
Highest bidder for listing 1: vishalgurdale2002
Internal Server Error: /register/
Traceback (most recent call last):
  File "C:\Users\prash\AppData\Local\Programs\Python\Python312\Lib\site-packages\django\core\handlers\exception.py", line 55, in inner
    response = get_response(request)
               ^^^^^^^^^^^^^^^^^^^^^
  File "C:\Users\prash\AppData\Local\Programs\Python\Python312\Lib\site-packages\django\core\handlers\base.py", line 197, in _get_response
    response = wrapped_callback(request, *callback_args, **callback_kwargs)
               ^^^^^^^^^^^^^^^^^^^^^^^^^^^^^^^^^^^^^^^^^^^^^^^^^^^^^^^^^^^^
  File "D:\projects\Auction System\BidBazaar\auctions\views.py", line 79, in register
    send_mail(
  File "C:\Users\prash\AppData\Local\Programs\Python\Python312\Lib\site-packages\django\core\mail\__init__.py", line 88, in send_mail
    return mail.send()
           ^^^^^^^^^^^
  File "C:\Users\prash\AppData\Local\Programs\Python\Python312\Lib\site-packages\django\core\mail\message.py", line 301, in send
    return self.get_connection(fail_silently).send_messages([self])
           ^^^^^^^^^^^^^^^^^^^^^^^^^^^^^^^^^^^^^^^^^^^^^^^^^^^^^^^^
  File "C:\Users\prash\AppData\Local\Programs\Python\Python312\Lib\site-packages\django\core\mail\backends\smtp.py", line 128, in send_messages
    new_conn_created = self.open()
                       ^^^^^^^^^^^
  File "C:\Users\prash\AppData\Local\Programs\Python\Python312\Lib\site-packages\django\core\mail\backends\smtp.py", line 95, in open
    self.connection.login(self.username, self.password)
  File "C:\Users\prash\AppData\Local\Programs\Python\Python312\Lib\smtplib.py", line 750, in login
    raise last_exception
  File "C:\Users\prash\AppData\Local\Programs\Python\Python312\Lib\smtplib.py", line 739, in login
    (code, resp) = self.auth(
                   ^^^^^^^^^^
  File "C:\Users\prash\AppData\Local\Programs\Python\Python312\Lib\smtplib.py", line 662, in auth
    raise SMTPAuthenticationError(code, resp)
smtplib.SMTPAuthenticationError: (535, b'5.7.8 Username and Password not accepted. For more information, go to\n5.7.8  https://support.google.com/mail/?p=BadCredentials d2e1a72fcca58-73971068576sm9211408b3a.119 - gsmtp')
